Workbook

Sheet EFECTIVO
F3: CANTIDAD | G3: CONTEO EN EFECTIVO
G4: BILLETES
F5: 5 | G5: 200 | H5: =F5*G5 -> 1000
C6: ELABORADO POR F. | F6: 1100 | G6: 100 | H6: =F6*G6 -> 110000
F7: 15 | G7: 50 | H7: =F7*G7 -> 750
F8: 29 | G8: 20 | H8: =F8*G8 -> 580
F9: 2 | G9: 10 | H9: =F9*G9 -> 20
F10: 141 | G10: 5 | H10: =F10*G10 -> 705
C11: COLABORADOR F. | F11: MONEDAS
F12: 1232 | G12: 1 | H12: =F12*G12 -> 1232
F13: 84 | G13: 0.5 | H13: =F13*G13 -> 42
F14: 173 | G14: 0.25 | H14: =F14*G14 -> 43.25
F15: 0 | G15: 0.1 | H15: =F15*G15 -> 0 | I15: TOTAL
C16: CONTADORA GENERAL F. | F16: 0 | G16: 0.05 | H16: =F16*G16 -> 0 | I16: =SUM(H5:H10)+H12+H13+H14+H15+H16+H17 -> 114372.25
F17: 0 | G17: 0.01 | H17: =F17*G17 -> 0

Sheet LIBRO DE CAJA (2)
T1: COOPERATIVA INTEGRAL DE AHORRO Y CREDITO
T2: "MAYA INVERSIONES FUTURAS" RESPONSABILIDAD LIMITADA
C3: TRANSACCIONES AGENTE Bi | I3: Ingresos y Egresos Propios | T3: Canton Ilom, Chajul Quiche | Z3: AUXILIAR DE CAJA AG. CHAJUL
C4: ING-Bi | E4: EG-Bi | K4: Ingresos | Q4: Egresos | T4: NIT: 6270731-0 | Z4: (Expresado en Quetzales)
A5: GN | C5: Servicios | D5: Depositos Mon. | F5: Retiro Mon. | G5: Remesa | I5: AhoCorriente | J5: Plazo Fijo | K5: Aportaciones | L5: Ingreso Asoc. | M5: Comisiones | N5: ABN Prestamos/INT./Mora y Otros | Q5: Colocacion | R5: EG | T5: FECHA | U5: Año | V5: Mes | W5: TIPO | X5: Doc. No | Y5: Cuenta No. | Z5: NOMBRE DEL BENEFICIARIO | AA5: DESCRIPCION | AD5: INGRESO | AE5: EGRESO | AF5: SALDO
A6: GN | Z6: SALDO INICIAL 2,026 | AF6: 81869.88
A7: GN | I7: 1 | T7: 46024 | U7: 2026 | V7: 01 | X7: 002235 | Y7: 1221-5-1 | Z7: IGLESIA EVANGELICA MISION JESUS FUENTE DE VIDA JUIL | AA7: DEPOSITO DE AHORRO CORRIENTE | AD7: 74000 | AE7: 0 | AF7: =AF6+AD7-AE7 -> 155869.88
A8: GN | I8: 2 | T8: 46024 | U8: 2026 | V8: 01 | X8: 002236 | Y8: 148-5-1 | Z8: MARIA RIVERA ESCOBAR | AA8: DEPOSITO DE AHORRO CORRIENTE | AD8: 15000 | AE8: 0 | AF8: =AF7+AD8-AE8 -> 170869.88
A9: GN | I9: 3 | T9: 46024 | U9: 2026 | V9: 01 | X9: 002237 | Y9: 415-5-1 | Z9: MARIA CECILIA IJOM RIVERA | AA9: DEPOSITO DE AHORRO CORRIENTE | AD9: 500 | AE9: 0 | AF9: =AF8+AD9-AE9 -> 171369.88
A10: GN | N10: 1 | T10: 46024 | U10: 2026 | V10: 01 | X10: 002238 | Y10: 67-2-2025 | Z10: ANDRES BRITO CHEL | AA10: ABONO SOBRE PRESTAMOS HIPOTECARIOS | AD10: 7864.36 | AE10: 0 | AF10: =AF9+AD10-AE10 -> 179234.24
A11: GN | N11: 1 | T11: 46024 | U11: 2026 | V11: 01 | X11: 002238 | Y11: 67-2-2025 | Z11: ANDRES BRITO CHEL | AA11: INTERESES HIPOTECARIOS | AD11: 4100.64 | AE11: 0 | AF11: =AF10+AD11-AE11 -> 183334.88
A12: GN | N12: 1 | T12: 46024 | U12: 2026 | V12: 01 | X12: 002238 | Y12: 67-2-2025 | Z12: ANDRES BRITO CHEL | AA12: MORA SOBRE PRESTAMOS HIPOTECARIOS | AD12: 35 | AE12: 0 | AF12: =AF11+AD12-AE12 -> 183369.88
A13: GN | N13: 2 | T13: 46024 | U13: 2026 | V13: 01 | X13: 002239 | Y13: 4-3-2025 | Z13: LORENZA RAQUEL PANTZAY SANCHEZ | AA13: ABONO SOBRE PRESTAMOS FIDUCIARIOS | AD13: 2311.37 | AE13: 0 | AF13: =AF12+AD13-AE13 -> 185681.25
N14: 2 | T14: 46024 | U14: 2026 | V14: 01 | X14: 002239 | Y14: 4-3-2025 | Z14: LORENZA RAQUEL PANTZAY SANCHEZ | AA14: INTERESES FIDUCIARIOS | AD14: 188.63 | AE14: 0 | AF14: =AF13+AD14-AE14 -> 185869.88
I15: 4 | T15: 46024 | U15: 2026 | V15: 01 | X15: 002240 | Y15: 4-5-1 | Z15: LORENZA RAQUEL PANTZAY SANCHEZ | AA15: DEPOSITO DE AHORRO CORRIENTE | AD15: 4000 | AE15: 0 | AF15: =AF14+AD15-AE15 -> 189869.88
N16: 3 | T16: 46024 | U16: 2026 | V16: 01 | X16: 002241 | Y16: 445-5-2025 | Z16: MARIA MARTA CABA MO | AA16: ABONO SOBRE PRESTAMOS FIDUCIARIOS | AD16: 684.39 | AE16: 0 | AF16: =AF15+AD16-AE16 -> 190554.27
N17: 3 | T17: 46024 | U17: 2026 | V17: 01 | X17: 002241 | Y17: 445-5-2025 | Z17: MARIA MARTA CABA MO | AA17: INTERESES FIDUCIARIOS | AD17: 115.61 | AE17: 0 | AF17: =AF16+AD17-AE17 -> 190669.88
R18: 1 | T18: 46024 | U18: 2026 | V18: 01 | X18: 0000582 | Y18: 588-5-1 | Z18: MARGARITA CABA CANAY | AA18: RETIRO DE AHORRO CORRIENTE | AD18: 0 | AE18: 300 | AF18: =AF17+AD18-AE18 -> 190369.88
R19: 2 | T19: 46024 | U19: 2026 | V19: 01 | X19: 0000583 | Y19: 148-5-1 | Z19: MARIA RIVERA ESCOBAR | AA19: RETIRO DE AHORRO CORRIENTE | AD19: 0 | AE19: 2000 | AF19: =AF18+AD19-AE19 -> 188369.88
R20: 3 | T20: 46024 | U20: 2026 | V20: 01 | W20: EG | X20: 0000584 | Y20: 17-6-1 | Z20: GASPAR ESCOBAR CABA | AA20: RETIRO DE AHORRO A PLAZO FIJO | AD20: 0 | AE20: 57000 | AF20: =AF19+AD20-AE20 -> 131369.88
R21: 3 | T21: 46024 | U21: 2026 | V21: 01 | W21: EG | X21: 0000584 | Y21: 17-6-1 | Z21: GASPAR ESCOBAR CABA | AA21: RETIRO DE AHORRO A PLAZO FIJO INTERES NETO | AD21: 0 | AE21: 7182 | AF21: =AF20+AD21-AE21 -> 124187.88
R22: 4 | T22: 46024 | U22: 2026 | V22: 01 | W22: EG | X22: 0000585 | Y22: 95-6-1 | Z22: JACINTA OFELIA PACHECO HIJOM | AA22: RETIRO DE AHORRO A PLAZO FIJO | AD22: 0 | AE22: 1000 | AF22: =AF21+AD22-AE22 -> 123187.88
R23: 4 | T23: 46024 | U23: 2026 | V23: 01 | W23: EG | X23: 0000585 | Y23: 95-6-1 | Z23: JACINTA OFELIA PACHECO HIJOM | AA23: RETIRO DE AHORRO A PLAZO FIJO INTERES NETO | AE23: 126 | AF23: =AF22+AD23-AE23 -> 123061.88
AA24: SUMAS- - - - - - - - - - | AD24: =SUM(AD7:AD23) -> 108800 | AE24: =SUM(AE18:AE23) -> 67608 | AF24: =AF6+AD24-AE24 -> 123061.88
A26: GN
A27: GN | Y27: BILLETES
A28: GN | X28: 240 | Y28: 200 | Z28: =X28*Y28 -> 48000
A29: GN | X29: 670 | Y29: 100 | Z29: =X29*Y29 -> 67000
A30: GN | X30: 94 | Y30: 50 | Z30: =X30*Y30 -> 4700
A31: GN | X31: 11 | Y31: 20 | Z31: =X31*Y31 -> 220
A32: GN | X32: 93 | Y32: 10 | Z32: =X32*Y32 -> 930
A33: GN | X33: 326 | Y33: 5 | Z33: =X33*Y33 -> 1630
A34: GN
A35: GN | X35: 537 | Y35: 1 | Z35: =X35*Y35 -> 537
A36: GN | X36: 46 | Y36: 0.5 | Z36: =X36*Y36 -> 23
A37: GN | X37: 87 | Y37: 0.25 | Z37: =X37*Y37 -> 21.75
A38: GN | X38: 1 | Y38: 0.1 | Z38: =X38*Y38 -> 0.1 | AA38: TOTAL
A39: GN | Y39: 0.05 | Z39: =X39*Y39 -> 0 | AA39: =SUM(Z28:Z33)+Z35+Z36+Z37+Z38+Z39+Z40 -> 123061.88
A40: GN | X40: 3 | Y40: 0.01 | Z40: =X40*Y40 -> 0.03
A41: GN | AA41: SALDO INICIAL DEL DIA - - - - - - - - - - | AF41: =AF24 -> 123061.88
...

Sheet Hoja1

Sheet Arqueo Caja Ag Chaj 22-06-2026
C1: Cooperativa Integral de Ahorro y Credito
C2: Maya Inversiones Futuras, R.L.
D3: Arqueo de Caja
D4: 22/06/2026 Hora: 03:00 pm a 05:00 pm
B5: Saldo Inicial (al 22/04/2026) Según Auxiliar | I5: ='LIBRO DE CAJA (2)'!AF2763 -> 52861.45
E6: (+) | F6: (-) | G6: (-) | H6: (-)
A7: (+) | B7: Fecha | C7: Doc. Ingreso | D7: Doc. Egreso | E7: Ingresos | F7: Egresos | G7: Depositos | H7: Facturas
B8: junio/2026 | C8: 2828 al 2863 | D8: 718 al 722 | E8: ='LIBRO DE CAJA (2)'!AD2949 -> 250445.54 | F8: ='LIBRO DE CAJA (2)'!AE2949-G8 -> 42509.62 | G8: ='LIBRO DE CAJA (2)'!AE2786+'LIBRO DE CAJA (2)'!AE2916+'LIBRO DE CAJA (2)'!AE2917+'LIBRO DE CAJA (2)'!AE2944 -> 141281.82 | H8: - | I8: =I5+E8-F8-G8 -> 119515.55
B9: julio/2026 | C9: 2864 al 3046 | D9: 723 al 786 | E9: ='LIBRO DE CAJA (2)'!AD3824 -> 1488659 | F9: ='LIBRO DE CAJA (2)'!AE3824-G9 -> 744416.31 | G9: ='LIBRO DE CAJA (2)'!AE3101+'LIBRO DE CAJA (2)'!AE3149+'LIBRO DE CAJA (2)'!AE3150+'LIBRO DE CAJA (2)'!AE3252+'LIBRO DE CAJA (2)'!AE3286+'LIBRO DE CAJA (2)'!AE3376+'LIBRO DE CAJA (2)'!AE3377+'LIBRO DE CAJA (2)'!AE3380+'LIBRO DE CAJA (2)'!AE3381+'LIBRO DE CAJA (2)'!AE3460+'LIBRO DE CAJA (2)'!AE3569+'LIBRO DE CAJA (2)'!AE3592 -> 773545.96 | H9: - | I9: =I8+E9-F9-G9 -> 90212.29
B10: agosto/2026 | C10: 3047 al 3129 | D10: 787 al 829 | E10: ='LIBRO DE CAJA (2)'!AD4442 -> 1766658.8 | F10: ='LIBRO DE CAJA (2)'!AE4442-G10 -> 539000.49 | G10: ='LIBRO DE CAJA (2)'!AE3846+'LIBRO DE CAJA (2)'!AE3871+'LIBRO DE CAJA (2)'!AE3874+'LIBRO DE CAJA (2)'!AE3905+'LIBRO DE CAJA (2)'!AE3907+'LIBRO DE CAJA (2)'!AE3966+'LIBRO DE CAJA (2)'!AE3969+'LIBRO DE CAJA (2)'!AE3983+'LIBRO DE CAJA (2)'!AE3985+'LIBRO DE CAJA (2)'!AE4113+'LIBRO DE CAJA (2)'!AE4115+'LIBRO DE CAJA (2)'!AE4120+'LIBRO DE CAJA (2)'!AE4122+'LIBRO DE CAJA (2)'!AE4124+'LIBRO DE CAJA (2)'!AE4127+'LIBRO DE CAJA (2)'!AE4128+'LIBRO DE CAJA (2)'!AE4135+'LIBRO DE CAJA (2)'!AE4137+'LIBRO DE CAJA (2)'!AE4168+'LIBRO DE CAJA (2)'!AE4170+'LIBRO DE CAJA (2)'!AE4199+'LIBRO DE CAJA (2)'!AE4315+'LIBRO DE CAJA (2)'!AE4316 -> 1260761.7 | I10: =I9+E10-F10-G10 -> 57108.94
C12: Total Ingresos | E12: =SUM(E8:E10) -> 3505763.4 | I12: =I5+E12-F13-G13 -> 57108.94
C13: Total de Egresos | D13: 0 | F13: =SUM(F8:F10) -> 1325926.4 | G13: =SUM(G8:G10) -> 2175589.5 | H13: =SUM(H8:H9) -> 0
B14: ARQUEO DEL EFECTIVO
C15: Recuento | D15: Cantidad | E15: Billetes | F15: Denominacion | H15: Total
D16: 36 | E16: Q.200.00 | F16: 200 | H16: =+F16*D16 -> 7200
D17: 487 | E17: Q.100.00 | F17: 100 | H17: =+F17*D17 -> 48700
D18: 0 | E18: Q.50.00 | F18: 50 | H18: =+F18*D18 -> 0
D19: 1 | E19: Q.20.00 | F19: 20 | H19: =+F19*D19 -> 20
D20: 0 | E20: Q.10.00 | F20: 10 | H20: =+F20*D20 -> 0
D21: 116 | E21: Q.5.00 | F21: 5 | H21: =+F21*D21 -> 580
D22: 0 | E22: Q.1.00 | F22: 1 | H22: =+F22*D22 -> 0
E23: Monedas | H23: =+F23*D23 -> 0
D24: 524 | E24: Q.1.00 | F24: 1 | H24: =+F24*D24 -> 524
D25: 81 | E25: Q.0.50 | F25: 0.5 | H25: =+F25*D25 -> 40.5
D26: 181 | E26: Q.0.25 | F26: 0.25 | H26: =+F26*D26 -> 45.25
D27: 2 | E27: Q.0.10 | F27: 0.1 | H27: =+F27*D27 -> 0.2
D28: 0 | E28: Q.0.05 | F28: 0.05 | H28: =+F28*D28 -> 0
D29: 0 | E29: Q.0.01 | F29: 0.01 | H29: =+F29*D29 -> 0
F30: Total Efectivo | I30: =SUM(H16:H29) -> 57109.95
F32: DIFERENCIA | I32: =I30-I12 -> 1.01
B33: El dia 22 de Junio de 2026 se hizo arqueo al Receptor Pagador María Juliana Laynez Laynez, en su presencia
B34: presentandonos los documentos de ingresos y egresos como tambien los depositos y
B35: facturas para proceder a realizar la revision se encontro un sobrante de Q. 0.00. Centavos de acuerdo con el
B36: arqueo y se incluyo con el total del efectivo encontrado. La diferencia radica en los centavos.
B37: El sobrante se queda en caja por decision unanime de la comision de vigilancia
B38: caso de faltante sera reembolsado de inmediato por la persona encargada cuando se hace el arqueo.
B39: Se devolvieron los documentos de forma íntegra a la persona encargada sin que haga falta
B40: alguno de los documentos recibiendolos en su entera satisfaccion.
B42: Observaciones:
B46: Rutilio Estanislao Sáenz Rivera | E46: Magdalena Guzman Marcos
...

Sheet Arqueo Caja Ag Chaj 22-04-2026
C1: Cooperativa Integral de Ahorro y Credito
C2: Maya Inversiones Futuras, R.L.
D3: Arqueo de Caja
D4: 22/04/2026 Hora: 03:00 pm a 05:00 pm
B5: Saldo Inicial (al 28/08/2026) Según Auxiliar | I5: ='LIBRO DE CAJA (2)'!AF1379 -> 134284.28
E6: (+) | F6: (-) | G6: (-) | H6: (-)
A7: (+) | B7: Fecha | C7: Doc. Ingreso | D7: Doc. Egreso | E7: Ingresos | F7: Egresos | G7: Depositos | H7: Facturas
B8: Marzo/2026 | C8: 2542 al 2713 | D8: 652 al 694 | E8: ='LIBRO DE CAJA (2)'!AD2254 -> 1639568.2 | F8: ='LIBRO DE CAJA (2)'!AE2254-G8 -> 559496.73 | G8: ='LIBRO DE CAJA (2)'!AE1437+'LIBRO DE CAJA (2)'!AE1503+'LIBRO DE CAJA (2)'!AE1504+'LIBRO DE CAJA (2)'!AE1527+'LIBRO DE CAJA (2)'!AE1528+'LIBRO DE CAJA (2)'!AE1551+'LIBRO DE CAJA (2)'!AE1597+'LIBRO DE CAJA (2)'!AE1598+'LIBRO DE CAJA (2)'!AE1624+'LIBRO DE CAJA (2)'!AE1680+'LIBRO DE CAJA (2)'!AE1738+'LIBRO DE CAJA (2)'!AE1761+'LIBRO DE CAJA (2)'!AE1786+'LIBRO DE CAJA (2)'!AE1820+'LIBRO DE CAJA (2)'!AE1858+'LIBRO DE CAJA (2)'!AE1859+'LIBRO DE CAJA (2)'!AE1923+'LIBRO DE CAJA (2)'!AE2027+'LIBRO DE CAJA (2)'!AE2062+'LIBRO DE CAJA (2)'!AE2090+'LIBRO DE CAJA (2)'!AE2144+'LIBRO DE CAJA (2)'!AE2167+'LIBRO DE CAJA (2)'!AE2199+'LIBRO DE CAJA (2)'!AE2240 -> 1077026.7 | H8: - | I8: =I5+E8-F8-G8 -> 137329.12
B9: Abril/2026 | C9: 2714 al 2827 | D9: 695 al 717 | E9: ='LIBRO DE CAJA (2)'!AD2763 -> 938006.72 | F9: ='LIBRO DE CAJA (2)'!AE2763-G9 -> 255370.67 | G9: ='LIBRO DE CAJA (2)'!AE2427+'LIBRO DE CAJA (2)'!AE2428+'LIBRO DE CAJA (2)'!AE2436+'LIBRO DE CAJA (2)'!AE2561+'LIBRO DE CAJA (2)'!AE2584+'LIBRO DE CAJA (2)'!AE2594+'LIBRO DE CAJA (2)'!AE2708 -> 767103.72 | H9: - | I9: =I8+E9-F9-G9 -> 52861.45
C12: Total Ingresos | E12: =SUM(E8:E10) -> 2577574.9 | I12: =I5+E12-F13-G13-H13 -> 52861.45
C13: Total de Egresos | D13: 0 | F13: =SUM(F8:F10) -> 814867.4 | G13: =SUM(G8:G10) -> 1844130.4 | H13: =SUM(H8:H9) -> 0
B14: ARQUEO DEL EFECTIVO
C15: Recuento | D15: Cantidad | E15: Billetes | F15: Denominacion | H15: Total
D16: 22 | E16: Q.200.00 | F16: 200 | H16: =+F16*D16 -> 4400
D17: 443 | E17: Q.100.00 | F17: 100 | H17: =+F17*D17 -> 44300
D18: 10 | E18: Q.50.00 | F18: 50 | H18: =+F18*D18 -> 500
D19: 3 | E19: Q.20.00 | F19: 20 | H19: =+F19*D19 -> 60
D20: 85 | E20: Q.10.00 | F20: 10 | H20: =+F20*D20 -> 850
D21: 319 | E21: Q.5.00 | F21: 5 | H21: =+F21*D21 -> 1595
D22: 0 | E22: Q.1.00 | F22: 1 | H22: =+F22*D22 -> 0
E23: Monedas | H23: =+F23*D23 -> 0
D24: 1071 | E24: Q.1.00 | F24: 1 | H24: =+F24*D24 -> 1071
D25: 80 | E25: Q.0.50 | F25: 0.5 | H25: =+F25*D25 -> 40
D26: 180 | E26: Q.0.25 | F26: 0.25 | H26: =+F26*D26 -> 45
D27: 4 | E27: Q.0.10 | F27: 0.1 | H27: =+F27*D27 -> 0.4
D28: 1 | E28: Q.0.05 | F28: 0.05 | H28: =+F28*D28 -> 0.05
D29: 0 | E29: Q.0.01 | F29: 0.01 | H29: =+F29*D29 -> 0
F30: Total Efectivo | I30: =SUM(H16:H29) -> 52861.45
F32: DIFERENCIA | I32: =I30-I12 -> 5.1659299e-10
B33: El dia 22 de Abril de 2026 se hizo arqueo al Receptor Pagador María Juliana Laynez Laynez, en su presencia
B34: presentandonos los documentos de ingresos y egresos como tambien los depositos y
B35: facturas para proceder a realizar la revision se encontro un sobrante de Q. 0.00. Centavos de acuerdo con el
B36: arqueo y se incluyo con el total del efectivo encontrado. La diferencia radica en los centavos.
B37: El sobrante se queda en caja por decision unanime de la comision de vigilancia
B38: caso de faltante sera reembolsado de inmediato por la persona encargada cuando se hace el arqueo.
B39: Se devolvieron los documentos de forma íntegra a la persona encargada sin que haga falta
B40: alguno de los documentos recibiendolos en su entera satisfaccion.
B42: Observaciones:
B46: Rutilio Estanislao Sáenz Rivera | E46: Magdalena Guzman Marcos
B47: Presidente | E47: Secretaria
...

Sheet Arqueo Caja Ag Chaj 28-02-2026
C1: Cooperativa Integral de Ahorro y Credito
C2: Maya Inversiones Futuras, R.L.
D3: Arqueo de Caja
D4: 28/02/2026 Hora: 8:30 am a 15:00 pm
B5: Saldo Inicial (al 31/12/2025) Según Auxiliar | I5: ='LIBRO DE CAJA (2)'!AF6 -> 81869.88
E6: (+) | F6: (-) | G6: (-) | H6: (-)
A7: (+) | B7: Fecha | C7: Doc. Ingreso | D7: Doc. Egreso | E7: Ingresos | F7: Egresos | G7: Depositos | H7: Facturas
B8: Enero/2026 | C8: 2235 al 2354 | D8: 582 al 616 | E8: ='LIBRO DE CAJA (2)'!AD642 -> 1495349.8 | F8: ='LIBRO DE CAJA (2)'!AE642-G8 -> 409846.35 | G8: ='LIBRO DE CAJA (2)'!AE161+'LIBRO DE CAJA (2)'!AE165+'LIBRO DE CAJA (2)'!AE190+'LIBRO DE CAJA (2)'!AE193+'LIBRO DE CAJA (2)'!AE235+'LIBRO DE CAJA (2)'!AE422+'LIBRO DE CAJA (2)'!AE446+'LIBRO DE CAJA (2)'!AE449+'LIBRO DE CAJA (2)'!AE472+'LIBRO DE CAJA (2)'!AE517+'LIBRO DE CAJA (2)'!AE583+'LIBRO DE CAJA (2)'!AE605+'LIBRO DE CAJA (2)'!AE608 -> 958523.11 | H8: - | I8: =I5+E8-F8-G8 -> 208850.23
B9: Febrero/2026 | C9: 2355 al 2541 | D9: 617 al 651 | E9: ='LIBRO DE CAJA (2)'!AD1379 -> 1233990.3 | F9: ='LIBRO DE CAJA (2)'!AE1379-G9 -> 429919.85 | G9: ='LIBRO DE CAJA (2)'!AE673+'LIBRO DE CAJA (2)'!AE676+'LIBRO DE CAJA (2)'!AE681+'LIBRO DE CAJA (2)'!AE701+'LIBRO DE CAJA (2)'!AE704+'LIBRO DE CAJA (2)'!AE737+'LIBRO DE CAJA (2)'!AE884+'LIBRO DE CAJA (2)'!AE910+'LIBRO DE CAJA (2)'!AE970+'LIBRO DE CAJA (2)'!AE971+'LIBRO DE CAJA (2)'!AE974+'LIBRO DE CAJA (2)'!AE1168+'LIBRO DE CAJA (2)'!AE1224+'LIBRO DE CAJA (2)'!AE1229+'LIBRO DE CAJA (2)'!AE1295+'LIBRO DE CAJA (2)'!AE1349+'LIBRO DE CAJA (2)'!AE1350+'LIBRO DE CAJA (2)'!AE1351 -> 878636.36 | H9: - | I9: =I8+E9-F9-G9 -> 134284.28
C12: Total Ingresos | E12: =SUM(E8:E10) -> 2729340.1 | I12: =I5+E12-F13-G13-H13 -> 134284.28
C13: Total de Egresos | D13: 0 | F13: =SUM(F8:F10) -> 839766.2 | G13: =SUM(G8:G10) -> 1837159.5 | H13: 0
B14: ARQUEO DEL EFECTIVO
C15: Recuento | D15: Cantidad | E15: Billetes | F15: Denominacion | H15: Total
D16: 10 | E16: Q.200.00 | F16: 200 | H16: =+F16*D16 -> 2000
D17: 516 | E17: Q.100.00 | F17: 100 | H17: =+F17*D17 -> 51600
D18: 12 | E18: Q.50.00 | F18: 50 | H18: =+F18*D18 -> 600
D19: 25 | E19: Q.20.00 | F19: 20 | H19: =+F19*D19 -> 500
D20: 4 | E20: Q.10.00 | F20: 10 | H20: =+F20*D20 -> 40
D21: 117 | E21: Q.5.00 | F21: 5 | H21: =+F21*D21 -> 585
E22: Q.1.00 | F22: 1 | H22: =+F22*D22 -> 0
E23: Monedas | H23: =+F23*D23 -> 0
D24: 1043 | E24: Q.1.00 | F24: 1 | H24: =+F24*D24 -> 1043
D25: 81 | E25: Q.0.50 | F25: 0.5 | H25: =+F25*D25 -> 40.5
D26: 176 | E26: Q.0.25 | F26: 0.25 | H26: =+F26*D26 -> 44
D27: 1 | E27: Q.0.10 | F27: 0.1 | H27: =+F27*D27 -> 0.1
E28: Q.0.05 | F28: 0.05 | H28: =+F28*D28 -> 0
D29: 1 | E29: Q.0.01 | F29: 0.01 | H29: =+F29*D29 -> 0.01
F30: Total Efectivo | I30: =SUM(H16:H29) -> 56452.61
F32: DIFERENCIA | I32: =I30-I12 -> -77831.67
B33: El dia 28 de Febrero de 2026 se hizo arqueo al Receptor Pagador Lorenza Raquel Pantzay Sánchez, en su presencia
B34: presentandonos los documentos de ingresos y egresos como tambien los depositos y
B35: facturas para proceder a realizar la revision se encontro un sobrante de Q. 0.00. Centavos de acuerdo con el
B36: arqueo y se incluyo con el total del efectivo encontrado. La diferencia radica en los centavos.
B37: El sobrante se queda en caja por decision unanime de la comision de vigilancia
B38: caso de faltante sera reembolsado de inmediato por la persona encargada cuando se hace el arqueo.
B39: Se devolvieron los documentos de forma íntegra a la persona encargada sin que haga falta
B40: alguno de los documentos recibiendolos en su entera satisfaccion.
B42: Observaciones:
B46: Rutilio Estanislao Sáenz Rivera | E46: Magdalena Guzman Marcos
B47: Presidente | E47: Secretaria
...

Sheet Arqueo Caja Ag Chaj 02-01-2026
C1: Cooperativa Integral de Ahorro y Credito
C2: Maya Inversiones Futuras, R.L.
D3: Arqueo de Caja
D4: 02/01/2026Hora: 10:00 pm a 13:00 pm
B5: Saldo Inicial (al 22/08/2025) Según Auxiliar | I5: ='LIBRO DE CAJA (2)'!#REF! -> #REF!
E6: (+) | F6: (-) | G6: (-) | H6: (-)
A7: (+) | B7: Fecha | C7: Doc. Ingreso | D7: Doc. Egreso | E7: Ingresos | F7: Egresos | G7: Depositos | H7: Facturas
B8: Octubre/2025 | C8: 1955 al 1971 | D8: 532 al 536 | E8: ='LIBRO DE CAJA (2)'!#REF! -> #REF! | F8: ='LIBRO DE CAJA (2)'!#REF! -> #REF! | H8: - | I8: =I5+E8-F8 -> #REF!
B9: Noviembre/2025 | C9: 1972 al 2050 | D9: 537 al 555 | E9: ='LIBRO DE CAJA (2)'!#REF! -> #REF! | F9: ='LIBRO DE CAJA (2)'!#REF!-G9 -> #REF! | G9: ='LIBRO DE CAJA (2)'!#REF!+'LIBRO DE CAJA (2)'!#REF!+'LIBRO DE CAJA (2)'!#REF!+'LIBRO DE CAJA (2)'!#REF!+'LIBRO DE CAJA (2)'!#REF!+'LIBRO DE CAJA (2)'!#REF!+'LIBRO DE CAJA (2)'!#REF!+'LIBRO DE CAJA (2)'!#REF! -> #REF! | H9: - | I9: =I8+E9-F9-G9 -> #REF!
B10: Diciembre/2025 | C10: 2051 al 2234 | D10: 556 al 581 | E10: ='LIBRO DE CAJA (2)'!AD139 -> 0 | F10: ='LIBRO DE CAJA (2)'!AE139-G10 -> #REF! | G10: ='LIBRO DE CAJA (2)'!AE66+'LIBRO DE CAJA (2)'!AE76+'LIBRO DE CAJA (2)'!#REF!+'LIBRO DE CAJA (2)'!#REF!+'LIBRO DE CAJA (2)'!#REF!+'LIBRO DE CAJA (2)'!#REF!+'LIBRO DE CAJA (2)'!#REF!+'LIBRO DE CAJA (2)'!AE80+'LIBRO DE CAJA (2)'!AE83+'LIBRO DE CAJA (2)'!AE137 -> #REF! | I10: =I9+E10-F10-G10 -> #REF!
C12: Total Ingresos | E12: =SUM(E8:E10) -> #REF! | I12: =I5+E12-F13-G13-H13 -> #REF!
C13: Total de Egresos | D13: 0 | F13: =SUM(F8:F10) -> #REF! | G13: =SUM(G8:G10) -> #REF! | H13: 0
B14: ARQUEO DEL EFECTIVO
C15: Recuento | D15: Cantidad | E15: Billetes | F15: Denominacion | H15: Total
D16: 236 | E16: Q.200.00 | F16: 200 | H16: =+F16*D16 -> 47200
D17: 271 | E17: Q.100.00 | F17: 100 | H17: =+F17*D17 -> 27100
D18: 84 | E18: Q.50.00 | F18: 50 | H18: =+F18*D18 -> 4200
D19: 11 | E19: Q.20.00 | F19: 20 | H19: =+F19*D19 -> 220
D20: 93 | E20: Q.10.00 | F20: 10 | H20: =+F20*D20 -> 930
D21: 327 | E21: Q.5.00 | F21: 5 | H21: =+F21*D21 -> 1635
E22: Q.1.00 | F22: 1 | H22: =+F22*D22 -> 0
E23: Monedas | H23: =+F23*D23 -> 0
D24: 525 | E24: Q.1.00 | F24: 1 | H24: =+F24*D24 -> 525
D25: 46 | E25: Q.0.50 | F25: 0.5 | H25: =+F25*D25 -> 23
D26: 87 | E26: Q.0.25 | F26: 0.25 | H26: =+F26*D26 -> 21.75
D27: 1 | E27: Q.0.10 | F27: 0.1 | H27: =+F27*D27 -> 0.1
D28: 0 | E28: Q.0.05 | F28: 0.05 | H28: =+F28*D28 -> 0
D29: 3 | E29: Q.0.01 | F29: 0.01 | H29: =+F29*D29 -> 0.03
F30: Total Efectivo | I30: =SUM(H16:H29) -> 81854.88
F32: DIFERENCIA | I32: =I30-I12 -> #REF!
B33: El dia 02 de Enero de 2026 se hizo arqueo al Receptor Pagador Lorenza Raquel Pantzay Sánchez, en su presencia
B34: presentandonos los documentos de ingresos y egresos como tambien los depositos y
B35: facturas para proceder a realizar la revision se encontro un sobrante de Q. 0.00. Centavos de acuerdo con el
B36: arqueo y se incluyo con el total del efectivo encontrado. La diferencia radica en los centavos.
B37: El sobrante se queda en caja por decision unanime de la comision de vigilancia
B38: caso de faltante sera reembolsado de inmediato por la persona encargada cuando se hace el arqueo.
B39: Se devolvieron los documentos de forma íntegra a la persona encargada sin que haga falta
B40: alguno de los documentos recibiendolos en su entera satisfaccion.
B42: Observaciones:
B46: Luis Santiago Ceto Bernal | E46: Magdalena Guzman Marcos
...

Sheet Arqueo Caja Ag Chaj 22-08-2025
C1: Cooperativa Integral de Ahorro y Credito
C2: Maya Inversiones Futuras, R.L.
D3: Arqueo de Caja
D4: 22/08/2025 Hora: 14:30 pm a 17:00 pm
B5: Saldo Inicial (al 24/06/2025) Según Auxiliar | I5: ='LIBRO DE CAJA (2)'!#REF! -> #REF!
E6: (+) | F6: (-) | G6: (-) | H6: (-)
A7: (+) | B7: Fecha | C7: Doc. Ingreso | D7: Doc. Egreso | E7: Ingresos | F7: Egresos | G7: Depositos | H7: Facturas
B8: Junio/20225 | C8: 1679 al 1702 | D8: 417 al 421 | E8: ='LIBRO DE CAJA (2)'!#REF! -> #REF! | F8: ='LIBRO DE CAJA (2)'!#REF!-G8 -> #REF! | G8: 0 | H8: - | I8: =I5+E8-F8 -> #REF!
B9: Julio/2025 | C9: 1703 al 1762 | D9: 422 al 455 | E9: ='LIBRO DE CAJA (2)'!#REF! -> #REF! | F9: ='LIBRO DE CAJA (2)'!#REF! -> #REF! | G9: 0 | H9: - | I9: =I8+E9-F9 -> #REF!
B10: Agosto/2025 | C10: 1763 al 1799 | D10: 456 al 476 | E10: ='LIBRO DE CAJA (2)'!#REF! -> #REF! | F10: ='LIBRO DE CAJA (2)'!#REF! -> #REF! | I10: =I9+E10-F10 -> #REF!
C12: Total Ingresos | E12: =SUM(E8:E10) -> #REF! | I12: =I5+E12-F13-G13-H13 -> #REF!
C13: Total de Egresos | D13: 0 | F13: =SUM(F8:F10) -> #REF! | G13: =SUM(G8:G10) -> 0 | H13: 0
B14: ARQUEO DEL EFECTIVO
C15: Recuento | D15: Cantidad | E15: Billetes | F15: Denominacion | H15: Total
D16: 5 | E16: Q.200.00 | F16: 200 | H16: =+F16*D16 -> 1000
D17: 545 | E17: Q.100.00 | F17: 100 | H17: =+F17*D17 -> 54500
D18: 1 | E18: Q.50.00 | F18: 50 | H18: =+F18*D18 -> 50
D19: 0 | E19: Q.20.00 | F19: 20 | H19: =+F19*D19 -> 0
D20: 100 | E20: Q.10.00 | F20: 10 | H20: =+F20*D20 -> 1000
D21: 334 | E21: Q.5.00 | F21: 5 | H21: =+F21*D21 -> 1670
E22: Q.1.00 | F22: 1 | H22: =+F22*D22 -> 0
E23: Monedas | H23: =+F23*D23 -> 0
D24: 400 | E24: Q.1.00 | F24: 1 | H24: =+F24*D24 -> 400
D25: 20 | E25: Q.0.50 | F25: 0.5 | H25: =+F25*D25 -> 10
D26: 33 | E26: Q.0.25 | F26: 0.25 | H26: =+F26*D26 -> 8.25
D27: 3 | E27: Q.0.10 | F27: 0.1 | H27: =+F27*D27 -> 0.3
D28: 0 | E28: Q.0.05 | F28: 0.05 | H28: =+F28*D28 -> 0
E29: Q.0.01 | F29: 0.01 | H29: =+F29*D29 -> 0
F30: Total Efectivo | I30: =SUM(H16:H29) -> 58638.55
F32: DIFERENCIA | I32: =I3 -> 0
B33: El dia 22 de Agosto de 2025 se hizo arqueo al Promotor de Crédito Diego Laynez Asiona, en su presencia
B34: presentandonos los documentos de ingresos y egresos como tambien los depositos y
B35: facturas para proceder a realizar la revision se encontro un sobrante de Q. 0.00. Centavos de acuerdo con el
B36: arqueo y se incluyo con el total del efectivo encontrado. La diferencia radica en los centavos.
B37: El sobrante se queda en caja por decision unanime de la comision de vigilancia
B38: caso de faltante sera reembolsado de inmediato por la persona encargada cuando se hace el arqueo.
B39: Se devolvieron los documentos de forma íntegra a la persona encargada sin que haga falta
B40: alguno de los documentos recibiendolos en su entera satisfaccion.
B42: Observaciones:
B46: Luis Santiago Ceto Bernal | E46: Magdalena Guzman Marcos
...

Sheet Arqueo Caja AG Chaj 24-04-2025
C1: Cooperativa Integral de Ahorro y Credito
C2: Maya Inversiones Futuras, R.L.
D3: Arqueo de Caja
D4: 24/04/2025 Hora: 14:30 pm a 16:30 pm
B5: Saldo Inicial (al 26/02/2025) Según Auxiliar | I5: =#REF! -> #REF!
E6: (+) | F6: (-) | G6: (-) | H6: (-)
A7: (+) | B7: Fecha | C7: Doc. Ingreso | D7: Doc. Egreso | E7: Ingresos | F7: Egresos | G7: Depositos | H7: Facturas
C8: 1421 al 1427 | D8: 324 al 324 | E8: =#REF! -> #REF! | F8: =#REF! -> #REF! | G8: 0 | H8: - | I8: =I5+E8-F8-G8 -> #REF!
B9: Marzo/2025 | C9: 1428 al 1485 | D9: 332 al 356 | E9: =#REF! -> #REF! | F9: =#REF! -> #REF! | G9: 0 | H9: - | I9: =I8+E9-F9-G9 -> #REF!
B10: Abril/2025 | C10: 1486 al 1543 | D10: 357 al 372 | E10: =#REF! -> #REF! | F10: =#REF! -> #REF! | I10: =+I9+E10-F10-G10 -> #REF!
C12: Total Ingresos | E12: =SUM(E8:E10) -> #REF! | I12: =I5+E12-F13-G13-H13 -> #REF!
C13: Total de Egresos | D13: 0 | F13: =SUM(F8:F10) -> #REF! | G13: =SUM(G8:G10) -> 0 | H13: 0
B14: ARQUEO DEL EFECTIVO
C15: Recuento | D15: Cantidad | E15: Billetes | F15: Denominacion | H15: Total
E16: Q.200.00 | F16: 200 | H16: =+F16*D16 -> 0
D17: 491 | E17: Q.100.00 | F17: 100 | H17: =+F17*D17 -> 49100
D18: 25 | E18: Q.50.00 | F18: 50 | H18: =+F18*D18 -> 1250
D19: 10 | E19: Q.20.00 | F19: 20 | H19: =+F19*D19 -> 200
D20: 4 | E20: Q.10.00 | F20: 10 | H20: =+F20*D20 -> 40
E21: Q.5.00 | F21: 5 | H21: =+F21*D21 -> 0
E22: Q.1.00 | F22: 1 | H22: =+F22*D22 -> 0
E23: Monedas | H23: =+F23*D23 -> 0
D24: 2 | E24: Q.1.00 | F24: 1 | H24: =+F24*D24 -> 2
D25: 2 | E25: Q.0.50 | F25: 0.5 | H25: =+F25*D25 -> 1
D26: 4 | E26: Q.0.25 | F26: 0.25 | H26: =+F26*D26 -> 1
E27: Q.0.10 | F27: 0.1 | H27: =+F27*D27 -> 0
D28: 1 | E28: Q.0.05 | F28: 0.05 | H28: =+F28*D28 -> 0.05
E29: Q.0.01 | F29: 0.01 | H29: =+F29*D29 -> 0
F30: Total Efectivo | I30: =SUM(H16:H29) -> 50594.05
F32: DIFERENCIA | I32: -0.01
B33: El dia 24 de Abril de 2025 se hizo arqueo al Receptor Pagador Lorenza Raquel Pantzay Sánchez, en su presencia
B34: presentandonos los documentos de ingresos y egresos como tambien los depositos y
B35: facturas para proceder a realizar la revision se encontro un sobrante de -Q. 0.02. Centavos de acuerdo con el | F35: -0.01
B36: arqueo y se incluyo con el total del efectivo encontrado. La diferencia radica en los centavos.
B37: El sobrante se queda en caja por decision unanime de la comision de vigilancia
B38: caso de faltante sera reembolsado de inmediato por la persona encargada cuando se hace el arqueo.
B39: Se devolvieron los documentos de forma íntegra a la persona encargada sin que haga falta
B40: alguno de los documentos recibiendolos en su entera satisfaccion.
B42: Observaciones:
B46: Luis Santiago Ceto Bernal | E46: Magdalena Guzman Marcos
...

Sheet Arqueo Caja AG Chaj 26-02-2025)
C1: Cooperativa Integral de Ahorro y Credito
C2: Maya Inversiones Futuras, R.L.
D3: Arqueo de Caja
D4: 26/02/2025 Hora: 14:00 pm a 16:30 pm
B5: Saldo Inicial (al 01/01/2025) Según Auxiliar | I5: =#REF! -> #REF!
E6: (+) | F6: (-) | G6: (-) | H6: (-)
A7: (+) | B7: Fecha | C7: Doc. Ingreso | D7: Doc. Egreso | E7: Ingresos | F7: Egresos | G7: Depositos | H7: Facturas
B8: Enero/2025 | C8: 1297 al 1368 | D8: 283 al 303 | E8: =#REF! -> #REF! | F8: =#REF!-G8 -> #REF! | G8: =#REF! -> #REF! | H8: - | I8: =I5+E8-F8-G8 -> #REF!
B9: Febrero/2025 | C9: 1369 al 1420 | D9: 304 al 323 | E9: =#REF! -> #REF! | F9: =#REF!-G9 -> #REF! | G9: =#REF!+#REF! -> #REF! | H9: - | I9: =I8+E9-F9-G9 -> #REF!
C11: Total Ingresos | E11: 850763.84 | I11: 95999.14
C12: Total de Egresos | D12: 0 | F12: 622773.63 | G12: 175000 | H12: 0
B13: ARQUEO DEL EFECTIVO
C14: Recuento | D14: Cantidad | E14: Billetes | F14: Denominacion | H14: Total
E15: Q.200.00 | F15: 200 | H15: -
D16: 914 | E16: Q.100.00 | F16: 100 | H16: 91400
E17: Q.50.00 | F17: 50 | H17: -
D18: 201 | E18: Q.20.00 | F18: 20 | H18: 4020
D19: 57 | E19: Q.10.00 | F19: 10 | H19: 570
D20: 1 | E20: Q.5.00 | F20: 5 | H20: 5
D21: 4 | E21: Q.1.00 | F21: 1 | H21: 4
E22: Monedas
E23: Q.1.00 | F23: 1 | H23: -
E24: Q.0.50 | F24: 0.5 | H24: -
E25: Q.0.25 | F25: 0.25 | H25: -
D26: 1 | E26: Q.0.10 | F26: 0.1 | H26: 0.1
D27: 1 | E27: Q.0.05 | F27: 0.05 | H27: 0.05
E28: Q.0.01 | F28: 0.01 | H28: -
F29: Total Efectivo | I29: 95999.15
F31: DIFERENCIA | I31: -0.01
B32: El dia 26 de Febrero de 2025 se hizo arqueo al Receptor Pagador Lorenza Raquel Pantzay Sánchez, en su presencia
B33: presentandonos los documentos de ingresos y egresos como tambien los depositos y
B34: facturas para proceder a realizar la revision se encontro un sobrante de -Q. 0.02. Centavos de acuerdo con el | F34: -0.01
B35: arqueo y se incluyo con el total del efectivo encontrado. La diferencia radica en los centavos.
B36: El sobrante se queda en caja por decision unanime de la comision de vigilancia
B37: caso de faltante sera reembolsado de inmediato por la persona encargada cuando se hace el arqueo.
B38: Se devolvieron los documentos de forma íntegra a la persona encargada sin que haga falta
B39: alguno de los documentos recibiendolos en su entera satisfaccion.
B41: Observaciones:
B45: Luis Santiago Ceto Bernal | E45: Magdalena Guzman Marcos
B46: Presidente | E46: Secretaria
...

Sheet Arqueo Caja AG Chaj 31-12-2024
C1: Cooperativa Integral de Ahorro y Credito
C2: "Maya Inversiones Futuras", R.L.
D3: Arqueo de Caja
D4: 31/12/2024 Hora:9:00 am a 11:00 am
B5: Saldo Inicial (al 18/11/2024) Según Auxiliar | I5: =#REF! -> #REF!
E6: (+) | F6: (-) | G6: (-) | H6: (-)
A7: (+) | B7: Fecha | C7: Doc. Ingreso | D7: Doc. Egreso | E7: Ingresos | F7: Egresos | G7: Depositos | H7: Facturas
B8: Noviembre/2024 | C8: 1139 al 1187 | D8: 255 al 260 | E8: =#REF! -> #REF! | F8: =#REF!-G8 -> #REF! | G8: =+#REF!+#REF!+#REF!+#REF! -> #REF! | H8: 0 | I8: =I5+E8-F8-G8-H8 -> #REF!
B9: Diciembre/2024 | C9: 1188 al 1296 | D9: 261 al 282 | E9: =#REF! -> #REF! | F9: =#REF!-G9 -> #REF! | G9: =#REF!+#REF!+#REF!+#REF! -> #REF! | H9: 0 | I9: =+I8+E9-F9-G9 -> #REF!
C10: Total Ingresos | E10: =SUM(E8:E9) -> #REF! | I10: =I5+E10-F11-G11-H11 -> #REF!
C11: Total de Egresos | D11: 0 | F11: =SUM(F8:F10) -> #REF! | G11: =SUM(G8:G10) -> #REF! | H11: =SUM(H8:H10) -> 0
B12: ARQUEO DEL EFECTIVO
C13: Recuento | D13: Cantidad | E13: Billetes | F13: Denominacion | H13: Total
D14: 37 | E14: Q.200.00 | F14: 200 | H14: =D14*F14 -> 7400
D15: 304 | E15: Q.100.00 | F15: 100 | H15: =D15*F15 -> 30400
D16: 4 | E16: Q.50.00 | F16: 50 | H16: =D16*F16 -> 200
D17: 1 | E17: Q.20.00 | F17: 20 | H17: =D17*F17 -> 20
D18: 400 | E18: Q.10.00 | F18: 10 | H18: =D18*F18 -> 4000
D19: 200 | E19: Q.5.00 | F19: 5 | H19: =D19*F19 -> 1000
D20: 0 | E20: Q.1.00 | F20: 1 | H20: =D20*F20 -> 0
E21: Monedas
D22: 51 | E22: Q.1.00 | F22: 1 | H22: =D22*F22 -> 51
D23: 1 | E23: Q.0.50 | F23: 0.5 | H23: =D23*F23 -> 0.5
D24: 1 | E24: Q.0.25 | F24: 0.25 | H24: =D24*F24 -> 0.25
D25: 1 | E25: Q.0.10 | F25: 0.1 | H25: =D25*F25 -> 0.1
D26: 1 | E26: Q.0.05 | F26: 0.05 | H26: =D26*F26 -> 0.05
E27: Q.0.01 | F27: 0.01 | H27: =D27*F27 -> 0
F28: Total Efectivo | I28: =SUM(H13:H28) -> 43071.9
F30: DIFERENCIA | I30: =I10-I28 -> #REF!
B31: El dia 31 de Diciembre de 2024 se hizo arqueo al Promotor de Créditos Diego Laynez Asicona, en su presencia
B32: presentandonos los documentos de ingresos y egresos como tambien los depositos y
B33: facturas para proceder a realizar la revision se encontro un sobrante de -Q. 0.02. Centavos de acuerdo con el | F33: =I30 -> #REF!
B34: arqueo y se incluyo con el total del efectivo encontrado. La diferencia radica en los centavos.
B35: El sobrante se queda en caja por decision unanime de la comision de vigilancia
A36: IIIIIIIIIIIIIIIIIIIIIIIIIIIIIIIIIIIIII | B36: caso de faltante sera reembolsado de inmediato por la persona encargada cuando se hace el arqueo.
B37: Se devolvieron los documentos de forma íntegra a la persona encargada sin que haga falta
B38: alguno de los documentos recibiendolos en su entera satisfaccion.
B40: Observaciones:
B44: Luis Santiago Ceto Bernal | E44: Magdalena Guzman Marcos
B45: Presidente | E45: Secretaria
...

Sheet Hoja3

Sheet Arqueo Caja AG Chaj 18-11-24
C1: Cooperativa Integral de Ahorro y Credito
C2: "Maya Inversiones Futuras", R.L.
D3: Arqueo de Caja
D4: 18/11/2024 Hora:9:00 am a 3:00 pm
B5: Saldo Inicial (al 09/03/2024) Según Auxiliar | I5: 23746.55
E6: (+) | F6: (-) | G6: (-) | H6: (-)
A7: (+) | B7: Fecha | C7: Doc. Ingreso | D7: Doc. Egreso | E7: Ingresos | F7: Egresos | G7: Depositos | H7: Facturas
B8: Marzo/2024 | C8: 631 al 664 | D8: 116 al 127 | E8: =+#REF! -> #REF! | F8: =+#REF!-G8 -> #REF! | G8: =+#REF!+#REF!+#REF!+#REF! -> #REF! | H8: 0 | I8: =I5+E8-F8-G8-H8 -> #REF!
B9: Abril/2024 | C9: 665 al 722 | D9: 128 al 140 | E9: =+#REF! -> #REF! | F9: =+#REF!-G9 -> #REF! | G9: =+#REF!+#REF!+#REF!+#REF!+#REF! -> #REF! | H9: 0 | I9: =+I8+E9-F9-G9 -> #REF!
B10: Mayo/2024 | C10: 723 al 782 | D10: 141 al 156 | E10: =+#REF! -> #REF! | F10: =+#REF!-G10 -> #REF! | G10: =+#REF!+#REF! -> #REF! | H10: 0 | I10: =+I9+E10-F10-G10-H10 -> #REF!
B11: Junio/2024 | C11: 783 al 821 | D11: 157 al 167 | E11: =+#REF! -> #REF! | F11: =+#REF!-G11 -> #REF! | G11: =+#REF!+#REF!+#REF!+#REF! -> #REF! | I11: =+I10+E11-F11-G11-H11 -> #REF!
B12: Julio/2024 | C12: 822 al 897 | D12: 168 al 182 | E12: =+#REF! -> #REF! | F12: =+#REF!-G12 -> #REF! | G12: =+#REF!+#REF!+#REF!+#REF!+#REF!+#REF!+#REF!+#REF! -> #REF! | I12: =+I11+E12-F12-G12-H12 -> #REF!
B13: Agosto/2024 | C13: 898 al 958 | D13: 183 al 202 | E13: =+#REF! -> #REF! | F13: =+#REF!-G13 -> #REF! | G13: =+#REF! -> #REF! | I13: =+I12+E13-F13-G13-H13 -> #REF!
B14: Septiembre/2024 | C14: 959 al 1028 | D14: 203 al 228 | E14: =+#REF! -> #REF! | F14: =+#REF!-G14 -> #REF! | G14: =+#REF!+#REF!+#REF!+#REF!+#REF!+#REF! -> #REF! | I14: =+I13+E14-F14-G14-H14 -> #REF!
B15: Octubre/2024 | C15: 1029 al 1101 | D15: 229 al 242 | E15: =+#REF! -> #REF! | F15: =+#REF!-G15 -> #REF! | G15: =+#REF!+#REF!+#REF!+#REF!+#REF!+#REF! -> #REF! | I15: =+I14+E15-F15-G15-H15 -> #REF!
B16: Noviembre/2024 | C16: 1102 al 1138 | D16: 244 al 254 | E16: =+#REF! -> #REF! | F16: =+#REF!-G16 -> #REF! | G16: =+#REF!+#REF! -> #REF! | I16: =+I15+E16-F16-G16-H16 -> #REF!
C17: Total Ingresos | E17: =SUM(E8:E16) -> #REF! | I17: =I5+E17-F18-G18-H18 -> #REF!
C18: Total de Egresos | D18: 0 | F18: =SUM(F8:F17) -> #REF! | G18: =SUM(G8:G17) -> #REF! | H18: =SUM(H8:H17) -> 0
B19: ARQUEO DEL EFECTIVO
C20: Recuento | D20: Cantidad | E20: Billetes | F20: Denominacion | H20: Total
D21: 9 | E21: Q.200.00 | F21: 200 | H21: =D21*F21 -> 1800
D22: 912 | E22: Q.100.00 | F22: 100 | H22: =D22*F22 -> 91200
D23: 0 | E23: Q.50.00 | F23: 50 | H23: =D23*F23 -> 0
D24: 0 | E24: Q.20.00 | F24: 20 | H24: =D24*F24 -> 0
D25: 4 | E25: Q.10.00 | F25: 10 | H25: =D25*F25 -> 40
D26: 95 | E26: Q.5.00 | F26: 5 | H26: =D26*F26 -> 475
E27: Q.1.00 | F27: 1 | H27: =D27*F27 -> 0
E28: Monedas
D29: 6 | E29: Q.1.00 | F29: 1 | H29: =D29*F29 -> 6
D30: 1 | E30: Q.0.50 | F30: 0.5 | H30: =D30*F30 -> 0.5
D31: 1 | E31: Q.0.25 | F31: 0.25 | H31: =D31*F31 -> 0.25
D32: 1 | E32: Q.0.10 | F32: 0.1 | H32: =D32*F32 -> 0.1
D33: 0 | E33: Q.0.05 | F33: 0.05 | H33: =D33*F33 -> 0
E34: Q.0.01 | F34: 0.01 | H34: =D34*F34 -> 0
F35: Total Efectivo | I35: =SUM(H20:H35) -> 93521.85
F37: DIFERENCIA | I37: =I17-I35 -> #REF!
B38: El dia 18 de Noviembre de 2024 se hizo arqueo al Receptor Pagador Lorenza Raquel Pantzay Sánchez, en su presencia
B39: presentandonos los documentos de ingresos y egresos como tambien los depositos y
B40: facturas para proceder a realizar la revision se encontro un sobrante de -Q. 0.02. Centavos de acuerdo con el
B41: arqueo y se incluyo con el total del efectivo encontrado. La diferencia radica en los centavos.
...

Sheet Arqueo Caja AG Chaj 08-03-24
C1: Cooperativa Integral de Ahorro y Credito
C2: "Maya Inversiones Futuras", R.L.
D3: Arqueo de Caja
D4: 08/03/2024 Hora:3:00 pm a 6:00 pm
B5: Saldo Inicial (al 03/11/2023) Según Auxiliar | I5: =+#REF! -> #REF!
E6: (+) | F6: (-) | G6: (-) | H6: (-)
A7: (+) | B7: Ingresos 2015 | C7: Doc. Ingreso | D7: Doc. Egreso | E7: Ingresos | F7: Egresos | G7: Depositos | H7: Facturas
B8: Noviembre/23 | C8: 380 al 431 | D8: 56 al 64 | E8: =+#REF! -> #REF! | F8: =+#REF!-G8 -> #REF! | G8: =+#REF!+#REF!+#REF!+#REF!+#REF!+#REF!+#REF!+#REF!+#REF!+#REF!++#REF!+#REF!+#REF! -> #REF! | H8: 0 | I8: =I5+E8-F8-G8-H8 -> #REF!
B9: Diciembre/23 | C9: 432 al 504 | D9: 65 al 79 | E9: =+#REF! -> #REF! | F9: =+#REF!-G9 -> #REF! | G9: =+#REF!+#REF!+#REF!+#REF! -> #REF! | H9: 0 | I9: =I8+E9-F9-G9-H9 -> #REF!
B10: Enero/2024 | C10: 505 al 561 | D10: 80 al 97 | E10: =+#REF! -> #REF! | F10: =+#REF!-G10 -> #REF! | G10: =+#REF!+#REF!+#REF!+#REF! -> #REF! | H10: 0 | I10: =I9+E10-F10-G10-H10 -> #REF!
B11: Febrero/2024 | C11: 562 al 612 | D11: 98 al 112 | E11: =+#REF! -> #REF! | F11: =+#REF!-G11 -> #REF! | G11: =+#REF!+#REF!+#REF!+#REF! -> #REF! | I11: =I10+E11-F11-G11-H11 -> #REF! | K11: =I10+E11-F11-G11 -> #REF!
B12: Marzo/2024 | C12: 613 al 630 | D12: 113 al 115 | E12: =+#REF! -> #REF! | F12: =+#REF!-G12 -> #REF! | G12: =+#REF!+#REF! -> #REF! | I12: =I11+E12-F12-G12-H12 -> #REF!
C14: Total Ingresos | E14: =SUM(E8:E13) -> #REF! | I14: =I5+E14-F15-G15-H15 -> #REF!
C15: Total de Egresos | D15: 0 | F15: =SUM(F8:F14) -> #REF! | G15: =SUM(G8:G14) -> #REF! | H15: =SUM(H8:H14) -> 0
B16: ARQUEO DEL EFECTIVO
C17: Recuento | D17: Cantidad | E17: Billetes | F17: Denominacion | H17: Total
D18: 20 | E18: Q.200.00 | F18: 200 | H18: =D18*F18 -> 4000
D19: 444 | E19: Q.100.00 | F19: 100 | H19: =D19*F19 -> 44400
D20: 2 | E20: Q.50.00 | F20: 50 | H20: =D20*F20 -> 100
D21: 13 | E21: Q.20.00 | F21: 20 | H21: =D21*F21 -> 260
D22: 3 | E22: Q.10.00 | F22: 10 | H22: =D22*F22 -> 30
D23: 4 | E23: Q.5.00 | F23: 5 | H23: =D23*F23 -> 20
E24: Q.1.00 | F24: 1 | H24: =D24*F24 -> 0
E25: Monedas
D26: 4 | E26: Q.1.00 | F26: 1 | H26: =D26*F26 -> 4
D27: 1 | E27: Q.0.50 | F27: 0.5 | H27: =D27*F27 -> 0.5
E28: Q.0.25 | F28: 0.25 | H28: =D28*F28 -> 0
E29: Q.0.10 | F29: 0.1 | H29: =D29*F29 -> 0
E30: Q.0.05 | F30: 0.05 | H30: =D30*F30 -> 0
E31: Q.0.01 | F31: 0.01 | H31: =D31*F31 -> 0
F32: Total Efectivo | I32: =SUM(H17:H32) -> 48814.5
F34: DIFERENCIA | I34: =I14-I32 -> #REF!
B35: El dia 02 de Noviembre de 2023 se hizo arqueo al Receptor Pagador Lorenza Raquel Pantzay Sánchez, en su presencia
B36: presentandonos los documentos de ingresos y egresos como tambien los depositos y
B37: facturas para proceder a realizar la revision se encontro un sobrante de -Q. 0.07. Centavos de acuerdo con el
B38: arqueo y se incluyo con el total del efectivo encontrado. La diferencia radica en los centavos.
B39: El sobrante Q.0.00 se deposita en la cuenta del banco por decision unanime de la comision de vigilancia
B40: caso de faltante sera reembolsado de inmediato por la persona encargada cuando se hace el arqueo.
B41: Se devolvieron los documentos de forma íntegra a la persona encargada sin que haga falta
B42: alguno de los documentos recibiendolos en su entera satisfaccion.
...

Sheet Arqueo Caja AG Chaj 02-11-23
C1: Cooperativa Integral de Ahorro y Credito
C2: "Maya Inversiones Futuras", R.L.
D3: Arqueo de Caja
D4: 02/11/2023 Hora:3:00 pm a 6:15 pm
B5: Saldo Inicial (al 27/04/2023) Según Auxiliar | I5: 33405.48
E6: (+) | F6: (-) | G6: (-) | H6: (-)
A7: (+) | B7: Ingresos 2015 | C7: Doc. Ingreso | D7: Doc. Egreso | E7: Igresos | F7: Egresos | G7: Depositos | H7: Facturas
B8: Agosto | C8: 256 al 280 | D8: 27 al 28 | E8: 225431 | F8: =226224-G8 -> 24825 | G8: =20455+46000+34250+94880+5814 -> 201399 | H8: 0 | I8: =I5+E8-F8-G8-H8 -> 32612.48
B9: Septiembre | C9: 281 al 334 | D9: 29 al 42 | E9: 494698.64 | F9: =495663-G9 -> 37000 | G9: =16364+50000+60000+15000+34054+17045+107882+15580+55240+45298+42200 -> 458663 | H9: 0 | I9: =I8+E9-F9-G9-H9 -> 31648.12
B10: octubre | C10: 335 al 379 | D10: 43 al 55 | E10: 358961.31 | F10: =341795-G10 -> 66800 | G10: =40000+34540+20455+110000+70000 -> 274995 | H10: 0 | I10: =I9+E10-F10-G10-H10 -> 48814.43
I11: =I10+E11-F11-G11-H11 -> 48814.43
I12: =I11+E12-F12-G12-H12 -> 48814.43
C14: Total Ingresos | E14: =SUM(E8:E13) -> 1079090.9 | I14: =I5+E14-F15-G15-H15 -> 48814.43
C15: Total de Egresos | D15: 0 | F15: =SUM(F8:F14) -> 128625 | G15: =SUM(G8:G14) -> 935057 | H15: =SUM(H8:H14) -> 0
B16: ARQUEO DEL EFECTIVO
C17: Recuento | D17: Cantidad | E17: Billetes | F17: Denominacion | H17: Total
D18: 20 | E18: Q.200.00 | F18: 200 | H18: =D18*F18 -> 4000
D19: 444 | E19: Q.100.00 | F19: 100 | H19: =D19*F19 -> 44400
D20: 2 | E20: Q.50.00 | F20: 50 | H20: =D20*F20 -> 100
D21: 13 | E21: Q.20.00 | F21: 20 | H21: =D21*F21 -> 260
D22: 3 | E22: Q.10.00 | F22: 10 | H22: =D22*F22 -> 30
D23: 4 | E23: Q.5.00 | F23: 5 | H23: =D23*F23 -> 20
E24: Q.1.00 | F24: 1 | H24: =D24*F24 -> 0
E25: Monedas
D26: 4 | E26: Q.1.00 | F26: 1 | H26: =D26*F26 -> 4
D27: 1 | E27: Q.0.50 | F27: 0.5 | H27: =D27*F27 -> 0.5
E28: Q.0.25 | F28: 0.25 | H28: =D28*F28 -> 0
E29: Q.0.10 | F29: 0.1 | H29: =D29*F29 -> 0
E30: Q.0.05 | F30: 0.05 | H30: =D30*F30 -> 0
E31: Q.0.01 | F31: 0.01 | H31: =D31*F31 -> 0
F32: Total Efectivo | I32: =SUM(H17:H32) -> 48814.5
F34: DIFERENCIA | I34: =I14-I32 -> -0.07
B35: El dia 02 de Noviembre de 2023 se hizo arqueo al Receptor Pagador Lorenza Raquel Pantzay Sánchez, en su presencia
B36: presentandonos los documentos de ingresos y egresos como tambien los depositos y
B37: facturas para proceder a realizar la revision se encontro un sobrante de -Q. 0.07. Centavos de acuerdo con el
B38: arqueo y se incluyo con el total del efectivo encontrado. La diferencia radica en los centavos.
B39: El sobrante Q.0.00 se deposita en la cuenta del banco por decision unanime de la comision de vigilancia
B40: caso de faltante sera reembolsado de inmediato por la persona encargada cuando se hace el arqueo.
B41: Se devolvieron los documentos de forma íntegra a la persona encargada sin que haga falta
B42: alguno de los documentos recibiendolos en su entera satisfaccion.
...

Sheet Hoja2
B1: Cooperativa Integral de Ahorro y Credito
B2: "Maya Inversiones Futuras", R.L.
C3: Arqueo de Caja
C4: 21/08/2023 Hora:3:00 pm a 6:15 pm
A5: Saldo Inicial (al 27/04/2023) Según Auxiliar | H5: =+#REF! -> #REF!
D6: (+) | E6: (-) | F6: (-) | G6: (-)
A7: Ingresos 2015 | B7: Doc. Ingreso | C7: Doc. Egreso | D7: Ingresos | E7: Egresos | F7: Depositos | G7: Facturas
A8: Agosto | B8: 256 al 280 | C8: 27 al 28 | D8: =+#REF! -> #REF! | E8: =#REF!-F8 -> #REF! | F8: 0 | G8: 0 | H8: =H5+D8-E8-F8-G8 -> #REF!
A9: Septiembre | B9: 281 al 331 | C9: 29 al 42 | D9: =+#REF! -> #REF! | E9: =+#REF!-F9-G9 -> #REF! | F9: =+#REF!+#REF!+#REF!+#REF!+#REF!+#REF!+#REF!+#REF! -> #REF! | G9: 0 | H9: =H8+D9-E9-F9-G9 -> #REF!
A10: Octubre | B10: 335 al 379 | C10: 43 AL 55 | D10: =+#REF! -> #REF! | E10: =+#REF!-F10-G10 -> #REF! | F10: =+#REF!+#REF!+#REF!+#REF!+#REF!+#REF!+#REF!+#REF! -> #REF! | G10: 0 | H10: =H9+D10-E10-F10-G10 -> #REF!
D11: =+#REF! -> #REF! | E11: =+#REF!-F11-G11 -> #REF! | F11: =+#REF!+#REF!+#REF!+#REF!+#REF!+#REF!+#REF!+#REF! -> #REF! | G11: 0 | H11: =H10+D11-E11-F11-G11 -> #REF!
D12: =+#REF! -> #REF! | E12: =+#REF!-F12-G12 -> #REF! | F12: =+#REF!+#REF!+#REF!+#REF!+#REF!+#REF! -> #REF! | G12: 0 | H12: =H11+D12-E12-F12-G12 -> #REF!
B14: Total Ingresos | D14: =SUM(D8:D13) -> #REF! | H14: =H5+D14-E15-F15-G15 -> #REF!
B15: Total de Egresos | C15: 0 | E15: =SUM(E8:E14) -> #REF! | F15: =SUM(F8:F14) -> #REF! | G15: =SUM(G8:G14) -> 0
A16: ARQUEO DEL EFECTIVO
B17: Recuento | C17: Cantidad | D17: Billetes | E17: Denominacion | G17: Total
D18: Q.200.00 | E18: 200 | G18: =C18*E18 -> 0
C19: 334 | D19: Q.100.00 | E19: 100 | G19: =C19*E19 -> 33400
D20: Q.50.00 | E20: 50 | G20: =C20*E20 -> 0
D21: Q.20.00 | E21: 20 | G21: =C21*E21 -> 0
D22: Q.10.00 | E22: 10 | G22: =C22*E22 -> 0
C23: 1 | D23: Q.5.00 | E23: 5 | G23: =C23*E23 -> 5
D24: Q.1.00 | E24: 1 | G24: =C24*E24 -> 0
D25: Monedas
D26: Q.1.00 | E26: 1 | G26: =C26*E26 -> 0
C27: 1 | D27: Q.0.50 | E27: 0.5 | G27: =C27*E27 -> 0.5
D28: Q.0.25 | E28: 0.25 | G28: =C28*E28 -> 0
D29: Q.0.10 | E29: 0.1 | G29: =C29*E29 -> 0
D30: Q.0.05 | E30: 0.05 | G30: =C30*E30 -> 0
D31: Q.0.01 | E31: 0.01 | G31: =C31*E31 -> 0
E32: Total Efectivo | H32: =SUM(G17:G32) -> 33405.5
E34: DIFERENCIA | H34: =H14-H32 -> #REF!
A35: El dia 21 de Agosto de 2023 se hizo arqueo al Receptor Pagador Lorenza Raquel Pantzay Sánchez, en su presencia
A36: presentandonos los documentos de ingresos y egresos como tambien los depositos y
A37: facturas para proceder a realizar la revision se encontro un sobrante de Q. 0.02. Centavos de acuerdo con el
A38: arqueo y se incluyo con el total del efectivo encontrado. La diferencia radica en los centavos.
A39: El sobrante Q.20.00 se deposita en la cuenta del banco por decision unanime de la comision de vigilancia
A40: caso de faltante sera reembolsado de inmediato por la persona encargada cuando se hace el arqueo.
A41: Se devolvieron los documentos de forma íntegra a la persona encargada sin que haga falta
A42: alguno de los documentos recibiendolos en su entera satisfaccion.
...
